<?xml version="1.0"?>
<robot xmlns:xacro="http://www.ros.org/wiki/xacro">

  <link
    name="base_foot_link">
    <inertial>
      <origin
        xyz="0.028709 -1.1762E-06 0.081128"
        rpy="0 0 0" />
      <mass
        value="2.8319" />
      <inertia
        ixx="0.016695"
        ixy="2.9518E-07"
        ixz="-0.0048838"
        iyy="0.050394"
        iyz="3.5697E-07"
        izz="0.057487" />
    </inertial>
    <visual>
      <origin
        xyz="0 0 0"
        rpy="0 0 0" />
      <geometry>
        <mesh
          filename="package://simulation_pkg/models/base_foot_link.STL" />
      </geometry>
      <material
        name="White">
        <color
          rgba="1 1 1 1" />
      </material>
    </visual>
    <collision>
      <origin
        xyz="0 0 0"
        rpy="0 0 0" />
      <geometry>
        <mesh
          filename="package://simulation_pkg/models/base_foot_link.STL" />
      </geometry>
    </collision>
  </link>

  <link
    name="base_link">
    <inertial>
      <origin
        xyz="0.028709 -1.1762E-06 0.047328"
        rpy="0 0 0" />
      <mass
        value="2.8319" />
      <inertia
        ixx="0.016695"
        ixy="2.9518E-07"
        ixz="-0.0048838"
        iyy="0.050394"
        iyz="3.5697E-07"
        izz="0.057487" />
    </inertial>
    <visual>
      <origin
        xyz="0 0 0"
        rpy="0 0 0" />
      <geometry>
        <mesh
          filename="package://simulation_pkg/models/base_link.STL" />
      </geometry>
      <material
        name="White">
        <color
          rgba="1 1 1 1" />
      </material>
    </visual>
    <collision>
      <origin
        xyz="0 0 0"
        rpy="0 0 0" />
      <geometry>
        <mesh
          filename="package://simulation_pkg/models/base_link.STL" />
      </geometry>
    </collision>
  </link>

  <joint
    name="base_link_joint"
    type="fixed">
    <origin
      xyz="0 0 0.0338"
      rpy="0 0 0" />
    <parent
      link="base_foot_link" />
    <child
      link="base_link" />
    <axis
      xyz="0 0 0" />
  </joint>

   <gazebo reference="base_link">
        <material>Gazebo/White</material>
    </gazebo>

  <link
    name="right_wheel_link">
    <inertial>
      <origin
        xyz="-6.0851E-08 -2.6479E-08 -0.0056934"
        rpy="0 0 0" />
      <mass
        value="0.033874" />
      <inertia
        ixx="1.2633E-05"
        ixy="2.297E-11"
        ixz="5.9989E-12"
        iyy="1.2633E-05"
        iyz="2.1353E-12"
        izz="2.3297E-05" />
    </inertial>
    <visual>
      <origin
        xyz="0 0 0"
        rpy="0 0 0" />
      <geometry>
        <mesh
          filename="package://simulation_pkg/models/right_wheel_link.STL" />
      </geometry>
      <material
        name="Black">
        <color
          rgba="0.1 0.1 0.1 1" />
      </material>
    </visual>
    <collision>
      <origin
        xyz="0 0 0"
        rpy="0 0 0" />
      <geometry>
        <cylinder radius="0.034" length="0.026" />
      </geometry>
    </collision>
  </link>

  <joint
    name="right_wheel_joint"
    type="continuous">
    <origin
      xyz="0 -0.10385 0"
      rpy="1.5708 0 0" />
    <parent
      link="base_link" />
    <child
      link="right_wheel_link" />
    <axis
      xyz="0 0 1" />
    <limit
      effort="100"
      velocity="10" />
    <dynamics
      damping="0.1"
      friction="0.1" />
  </joint>

  <gazebo reference="right_wheel_link">
    <material>Gazebo/Black</material>
    <mu1>2.0</mu1>
    <mu2>2.0</mu2>
    <kp>1e6</kp>
    <kd>1.0</kd>
  </gazebo>

  <link
    name="left_wheel_link">
    <inertial>
      <origin
        xyz="1.2777E-08 6.5121E-08 0.0056934"
        rpy="0 0 0" />
      <mass
        value="0.033874" />
      <inertia
        ixx="1.2633E-05"
        ixy="-3.7029E-11"
        ixz="7.9558E-13"
        iyy="1.2633E-05"
        iyz="6.3177E-12"
        izz="2.3297E-05" />
    </inertial>
    <visual>
      <origin
        xyz="0 0 0"
        rpy="0 0 0" />
      <geometry>
        <mesh
          filename="package://simulation_pkg/models/left_wheel_link.STL" />
      </geometry>
      <material
        name="Black">
        <color
          rgba="0.1 0.1 0.1 1" />
      </material>
    </visual>
    <collision>
      <origin
        xyz="0 0 0"
        rpy="0 0 0" />
      <geometry>
        <cylinder radius="0.034" length="0.026" />
      </geometry>
    </collision>
  </link>

  <joint
    name="left_wheel_joint"
    type="continuous">
    <origin
      xyz="0 0.10385 0"
      rpy="1.5708 0 0" />
    <parent
      link="base_link" />
    <child
      link="left_wheel_link" />
    <axis
      xyz="0 0 1" />
    <limit
      effort="100"
      velocity="10" />
    <dynamics
      damping="0.1"
      friction="0.1" />
  </joint>

  <gazebo reference="left_wheel_link">
    <material>Gazebo/Black</material>
    <mu1>2.0</mu1>
    <mu2>2.0</mu2>
    <kp>1e6</kp>
    <kd>1.0</kd>
  </gazebo>

  <link
    name="front_caster_link">
    <inertial>
      <origin
        xyz="-0.0089009 -1.9819E-08 0.031166"
        rpy="0 0 0" />
      <mass
        value="0.032606" />
      <inertia
        ixx="4.0455E-06"
        ixy="-1.2329E-12"
        ixz="1.0515E-07"
        iyy="4.5906E-06"
        iyz="5.9156E-12"
        izz="5.9799E-06" />
    </inertial>
    <visual>
      <origin
        xyz="0 0 0"
        rpy="0 0 0" />
      <geometry>
        <mesh
          filename="package://simulation_pkg/models/front_caster_link.STL" />
      </geometry>
      <material
        name="Blue">
        <color
          rgba="0.1 0.3 0.8 1" />
      </material>
    </visual>
    <collision>
      <origin
        xyz="0 0 0"
        rpy="0 0 0" />
      <geometry>
        <mesh
          filename="package://simulation_pkg/models/front_caster_link.STL" />
      </geometry>
    </collision>
  </link>

  <joint
    name="front_caster_joint"
    type="fixed">
    <origin
      xyz="0.16904 0 -0.033801"
      rpy="0 0 0" />
    <parent
      link="base_link" />
    <child
      link="front_caster_link" />
    <axis
      xyz="0 0 0" />
    <!-- <dynamics
      damping="0"
      friction="0.001" /> -->
  </joint>

  <gazebo reference="front_caster_link">
    <material>Gazebo/Blue</material>
    <mu1>0.0</mu1>
    <mu2>0.0</mu2>
  </gazebo>

  <link
    name="rear_caster_link">
    <inertial>
      <origin
        xyz="0.0089009 1.9819E-08 0.031166"
        rpy="0 0 0" />
      <mass
        value="0.032606" />
      <inertia
        ixx="4.0455E-06"
        ixy="-1.2329E-12"
        ixz="-1.0515E-07"
        iyy="4.5906E-06"
        iyz="-5.9156E-12"
        izz="5.9799E-06" />
    </inertial>
    <visual>
      <origin
        xyz="0 0 0"
        rpy="0 0 0" />
      <geometry>
        <mesh
          filename="package://simulation_pkg/models/rear_caster_link.STL" />
      </geometry>
      <material
        name="Blue">
        <color
          rgba="0.1 0.3 0.8 1" />
      </material>
    </visual>
    <collision>
      <origin
        xyz="0 0 0"
        rpy="0 0 0" />
      <geometry>
        <mesh
          filename="package://simulation_pkg/models/rear_caster_link.STL" />
      </geometry>
    </collision>
  </link>

  <joint
    name="rear_caster_joint"
    type="fixed">
    <origin
      xyz="-0.15694 0 -0.033801"
      rpy="0 0 0" />
    <parent
      link="base_link" />
    <child
      link="rear_caster_link" />
    <axis
      xyz="0 0 0" />
    <!-- <dynamics
      damping="0"
      friction="0.001" /> -->
  </joint>

  <gazebo reference="rear_caster_link">
    <material>Gazebo/Blue</material>
    <mu1>0.0</mu1>
    <mu2>0.0</mu2>
  </gazebo>

  <link
    name="lidar_link">
    <inertial>
      <origin
        xyz="-0.0004791 -0.012128 -0.028959"
        rpy="0 0 0" />
      <mass
        value="0.073606" />
      <inertia
        ixx="2.414E-05"
        ixy="1.0407E-07"
        ixz="9.3871E-09"
        iyy="1.9594E-05"
        iyz="4.2835E-07"
        izz="4.1421E-05" />
    </inertial>
    <visual>
      <origin
        xyz="0 0 0"
        rpy="0 0 0" />
      <geometry>
        <mesh
          filename="package://simulation_pkg/models/lidar_link.STL" />
      </geometry>
      <material
        name="Black">
        <color
          rgba="0.1 0.1 0.1 1" />
      </material>
    </visual>
    <collision>
      <origin
        xyz="0 0 0"
        rpy="0 0 0" />
      <geometry>
        <mesh
          filename="package://simulation_pkg/models/lidar_link.STL" />
      </geometry>
    </collision>
  </link>

  <joint
    name="lidar_joint"
    type="fixed">
    <origin
      xyz="0.10399 0.012103 0.215"
      rpy="0 0 0" />
    <parent
      link="base_link" />
    <child
      link="lidar_link" />
    <axis
      xyz="0 0 0" />
  </joint>

  <gazebo reference="lidar_link">
        <material>Gazebo/Black</material>
    </gazebo>

  <link
    name="camera_link">
    <inertial>
      <origin
        xyz="-6.3245E-05 -0.00013858 -0.001753"
        rpy="0 0 0" />
      <mass
        value="0.0012611" />
      <inertia
        ixx="7.3712E-08"
        ixy="-3.4395E-12"
        ixz="-1.7868E-11"
        iyy="3.4448E-08"
        iyz="4.4653E-10"
        izz="4.0006E-08" />
    </inertial>
    <visual>
      <origin
        xyz="0 0 0"
        rpy="0 0 0" />
      <geometry>
        <mesh
          filename="package://simulation_pkg/models/camera_link.STL" />
      </geometry>
      <material
        name="Green">
        <color
          rgba="0.1 0.8 0.1 1" />
      </material>
    </visual>
    <collision>
      <origin
        xyz="0 0 0"
        rpy="0 0 0" />
      <geometry>
        <mesh
          filename="package://simulation_pkg/models/camera_link.STL" />
      </geometry>
    </collision>
  </link>

  <joint
    name="camera_joint"
    type="fixed">
    <origin
      xyz="0.20604 0 0.16311"
      rpy="0 0 0" />
    <parent
      link="base_link" />
    <child
      link="camera_link" />
    <axis
      xyz="0 0 0" />
  </joint>

  <joint
    name="camera_optical_joint"
    type="fixed">
    <origin
      xyz="0 0 0"
      rpy="-1.5708 0 -1.5708" />
    <parent
      link="camera_link" />
    <child
      link="camera_link_optical" />
    <axis
      xyz="0 0 0" />
  </joint>

  <link name="camera_link_optical"></link>

  <gazebo reference="camera_link">
        <material>Gazebo/Green</material>
    </gazebo>

</robot>
